[2022-05-15 19:43:18,327] {taskinstance.py:1035} INFO - Dependencies all met for <TaskInstance: orchestrator.load_data manual__2022-05-15T19:42:55.820330+00:00 [queued]>
[2022-05-15 19:43:18,327] {taskinstance.py:1035} INFO - Dependencies all met for <TaskInstance: orchestrator.load_data scheduled__2022-05-14T00:00:00+00:00 [queued]>
[2022-05-15 19:43:18,355] {taskinstance.py:1035} INFO - Dependencies all met for <TaskInstance: orchestrator.load_data manual__2022-05-15T19:42:55.820330+00:00 [queued]>
[2022-05-15 19:43:18,355] {taskinstance.py:1241} INFO - 
--------------------------------------------------------------------------------
[2022-05-15 19:43:18,355] {taskinstance.py:1242} INFO - Starting attempt 1 of 2
[2022-05-15 19:43:18,355] {taskinstance.py:1243} INFO - 
--------------------------------------------------------------------------------
[2022-05-15 19:43:18,366] {taskinstance.py:1035} INFO - Dependencies all met for <TaskInstance: orchestrator.load_data scheduled__2022-05-14T00:00:00+00:00 [queued]>
[2022-05-15 19:43:18,366] {taskinstance.py:1241} INFO - 
--------------------------------------------------------------------------------
[2022-05-15 19:43:18,366] {taskinstance.py:1242} INFO - Starting attempt 1 of 2
[2022-05-15 19:43:18,366] {taskinstance.py:1243} INFO - 
--------------------------------------------------------------------------------
[2022-05-15 19:43:18,399] {taskinstance.py:1262} INFO - Executing <Task(PythonOperator): load_data> on 2022-05-15 19:42:55.820330+00:00
[2022-05-15 19:43:18,404] {standard_task_runner.py:52} INFO - Started process 1226 to run task
[2022-05-15 19:43:18,408] {standard_task_runner.py:76} INFO - Running: ['***', 'tasks', 'run', 'orchestrator', 'load_data', 'manual__2022-05-15T19:42:55.820330+00:00', '--job-id', '56', '--raw', '--subdir', 'DAGS_FOLDER/pipeline.py', '--cfg-path', '/tmp/tmprcbljyun', '--error-file', '/tmp/tmpvgqhvjgx']
[2022-05-15 19:43:18,409] {standard_task_runner.py:77} INFO - Job 56: Subtask load_data
[2022-05-15 19:43:18,411] {taskinstance.py:1262} INFO - Executing <Task(PythonOperator): load_data> on 2022-05-14 00:00:00+00:00
[2022-05-15 19:43:18,415] {standard_task_runner.py:52} INFO - Started process 1227 to run task
[2022-05-15 19:43:18,420] {standard_task_runner.py:76} INFO - Running: ['***', 'tasks', 'run', 'orchestrator', 'load_data', 'scheduled__2022-05-14T00:00:00+00:00', '--job-id', '55', '--raw', '--subdir', 'DAGS_FOLDER/pipeline.py', '--cfg-path', '/tmp/tmpjt2jjtgf', '--error-file', '/tmp/tmp195x0stu']
[2022-05-15 19:43:18,420] {standard_task_runner.py:77} INFO - Job 55: Subtask load_data
[2022-05-15 19:43:18,479] {logging_mixin.py:109} INFO - Running <TaskInstance: orchestrator.load_data manual__2022-05-15T19:42:55.820330+00:00 [running]> on host 87efc59194bd
[2022-05-15 19:43:18,503] {logging_mixin.py:109} INFO - Running <TaskInstance: orchestrator.load_data scheduled__2022-05-14T00:00:00+00:00 [running]> on host 87efc59194bd
[2022-05-15 19:43:18,615] {taskinstance.py:1414} INFO - Exporting the following env vars:
AIRFLOW_CTX_DAG_EMAIL=***@example.com
AIRFLOW_CTX_DAG_OWNER=***
AIRFLOW_CTX_DAG_ID=orchestrator
AIRFLOW_CTX_TASK_ID=load_data
AIRFLOW_CTX_EXECUTION_DATE=2022-05-15T19:42:55.820330+00:00
AIRFLOW_CTX_DAG_RUN_ID=manual__2022-05-15T19:42:55.820330+00:00
[2022-05-15 19:43:18,616] {load.py:17} INFO - Starting process load star schema
[2022-05-15 19:43:18,636] {base.py:79} INFO - Using connection to: id: MySql Localhost. Host: 192.168.15.14, Port: 3306, Schema: , Login: db_user, Password: ***, extra: {}
[2022-05-15 19:43:18,638] {taskinstance.py:1414} INFO - Exporting the following env vars:
AIRFLOW_CTX_DAG_EMAIL=***@example.com
AIRFLOW_CTX_DAG_OWNER=***
AIRFLOW_CTX_DAG_ID=orchestrator
AIRFLOW_CTX_TASK_ID=load_data
AIRFLOW_CTX_EXECUTION_DATE=2022-05-14T00:00:00+00:00
AIRFLOW_CTX_DAG_RUN_ID=scheduled__2022-05-14T00:00:00+00:00
[2022-05-15 19:43:18,639] {load.py:17} INFO - Starting process load star schema
[2022-05-15 19:43:18,659] {base.py:79} INFO - Using connection to: id: MySql Localhost. Host: 192.168.15.14, Port: 3306, Schema: , Login: db_user, Password: ***, extra: {}
[2022-05-15 19:43:19,137] {load.py:39} INFO - Creating Dim Torrent
[2022-05-15 19:43:19,153] {base.py:79} INFO - Using connection to: id: MySql Localhost. Host: 192.168.15.14, Port: 3306, Schema: , Login: db_user, Password: ***, extra: {}
[2022-05-15 19:43:19,198] {load.py:39} INFO - Creating Dim Torrent
[2022-05-15 19:43:19,215] {base.py:79} INFO - Using connection to: id: MySql Localhost. Host: 192.168.15.14, Port: 3306, Schema: , Login: db_user, Password: ***, extra: {}
[2022-05-15 19:43:20,617] {load.py:66} ERROR - Error to load start schema: (pymysql.err.OperationalError) (1050, "Table 'DimTorrent' already exists")
[SQL: 
CREATE TABLE `DimTorrent` (
	torrent_id BIGINT, 
	url_torrent TEXT, 
	size TEXT, 
	size_bytes BIGINT, 
	type TEXT, 
	quality TEXT, 
	language TEXT, 
	uploaded_torrent_at DATETIME, 
	created_at TIMESTAMP NULL, 
	updated_at TIMESTAMP NULL, 
	loaded_at TIMESTAMP NULL, 
	loaded_by TEXT
)

]
(Background on this error at: http://sqlalche.me/e/13/e3q8)
[2022-05-15 19:43:20,635] {base.py:79} INFO - Using connection to: id: MySql Localhost. Host: 192.168.15.14, Port: 3306, Schema: , Login: db_user, Password: ***, extra: {}
[2022-05-15 19:43:20,771] {taskinstance.py:1686} ERROR - Task failed with exception
Traceback (most recent call last):
  File "/home/airflow/.local/lib/python3.6/site-packages/sqlalchemy/engine/base.py", line 1277, in _execute_context
    cursor, statement, parameters, context
  File "/home/airflow/.local/lib/python3.6/site-packages/sqlalchemy/engine/default.py", line 608, in do_execute
    cursor.execute(statement, parameters)
  File "/usr/local/lib/python3.6/site-packages/pymysql/cursors.py", line 148, in execute
    result = self._query(query)
  File "/usr/local/lib/python3.6/site-packages/pymysql/cursors.py", line 310, in _query
    conn.query(q)
  File "/usr/local/lib/python3.6/site-packages/pymysql/connections.py", line 548, in query
    self._affected_rows = self._read_query_result(unbuffered=unbuffered)
  File "/usr/local/lib/python3.6/site-packages/pymysql/connections.py", line 775, in _read_query_result
    result.read()
  File "/usr/local/lib/python3.6/site-packages/pymysql/connections.py", line 1156, in read
    first_packet = self.connection._read_packet()
  File "/usr/local/lib/python3.6/site-packages/pymysql/connections.py", line 725, in _read_packet
    packet.raise_for_error()
  File "/usr/local/lib/python3.6/site-packages/pymysql/protocol.py", line 221, in raise_for_error
    err.raise_mysql_exception(self._data)
  File "/usr/local/lib/python3.6/site-packages/pymysql/err.py", line 143, in raise_mysql_exception
    raise errorclass(errno, errval)
pymysql.err.OperationalError: (1050, "Table 'DimTorrent' already exists")

The above exception was the direct cause of the following exception:

Traceback (most recent call last):
  File "/opt/airflow/dags/ETL/load.py", line 57, in LoadStartSchema
    df_torrent.to_sql('DimTorrent',dbcon_write,if_exists='replace',index=False)
  File "/home/airflow/.local/lib/python3.6/site-packages/pandas/core/generic.py", line 2615, in to_sql
    method=method,
  File "/home/airflow/.local/lib/python3.6/site-packages/pandas/io/sql.py", line 598, in to_sql
    method=method,
  File "/home/airflow/.local/lib/python3.6/site-packages/pandas/io/sql.py", line 1393, in to_sql
    table.create()
  File "/home/airflow/.local/lib/python3.6/site-packages/pandas/io/sql.py", line 732, in create
    self._execute_create()
  File "/home/airflow/.local/lib/python3.6/site-packages/pandas/io/sql.py", line 718, in _execute_create
    self.table.create()
  File "/home/airflow/.local/lib/python3.6/site-packages/sqlalchemy/sql/schema.py", line 928, in create
    bind._run_visitor(ddl.SchemaGenerator, self, checkfirst=checkfirst)
  File "/home/airflow/.local/lib/python3.6/site-packages/sqlalchemy/engine/base.py", line 2095, in _run_visitor
    conn._run_visitor(visitorcallable, element, **kwargs)
  File "/home/airflow/.local/lib/python3.6/site-packages/sqlalchemy/engine/base.py", line 1656, in _run_visitor
    visitorcallable(self.dialect, self, **kwargs).traverse_single(element)
  File "/home/airflow/.local/lib/python3.6/site-packages/sqlalchemy/sql/visitors.py", line 145, in traverse_single
    return meth(obj, **kw)
  File "/home/airflow/.local/lib/python3.6/site-packages/sqlalchemy/sql/ddl.py", line 832, in visit_table
    include_foreign_key_constraints,  # noqa
  File "/home/airflow/.local/lib/python3.6/site-packages/sqlalchemy/engine/base.py", line 1011, in execute
    return meth(self, multiparams, params)
  File "/home/airflow/.local/lib/python3.6/site-packages/sqlalchemy/sql/ddl.py", line 72, in _execute_on_connection
    return connection._execute_ddl(self, multiparams, params)
  File "/home/airflow/.local/lib/python3.6/site-packages/sqlalchemy/engine/base.py", line 1073, in _execute_ddl
    compiled,
  File "/home/airflow/.local/lib/python3.6/site-packages/sqlalchemy/engine/base.py", line 1317, in _execute_context
    e, statement, parameters, cursor, context
  File "/home/airflow/.local/lib/python3.6/site-packages/sqlalchemy/engine/base.py", line 1511, in _handle_dbapi_exception
    sqlalchemy_exception, with_traceback=exc_info[2], from_=e
  File "/home/airflow/.local/lib/python3.6/site-packages/sqlalchemy/util/compat.py", line 182, in raise_
    raise exception
  File "/home/airflow/.local/lib/python3.6/site-packages/sqlalchemy/engine/base.py", line 1277, in _execute_context
    cursor, statement, parameters, context
  File "/home/airflow/.local/lib/python3.6/site-packages/sqlalchemy/engine/default.py", line 608, in do_execute
    cursor.execute(statement, parameters)
  File "/usr/local/lib/python3.6/site-packages/pymysql/cursors.py", line 148, in execute
    result = self._query(query)
  File "/usr/local/lib/python3.6/site-packages/pymysql/cursors.py", line 310, in _query
    conn.query(q)
  File "/usr/local/lib/python3.6/site-packages/pymysql/connections.py", line 548, in query
    self._affected_rows = self._read_query_result(unbuffered=unbuffered)
  File "/usr/local/lib/python3.6/site-packages/pymysql/connections.py", line 775, in _read_query_result
    result.read()
  File "/usr/local/lib/python3.6/site-packages/pymysql/connections.py", line 1156, in read
    first_packet = self.connection._read_packet()
  File "/usr/local/lib/python3.6/site-packages/pymysql/connections.py", line 725, in _read_packet
    packet.raise_for_error()
  File "/usr/local/lib/python3.6/site-packages/pymysql/protocol.py", line 221, in raise_for_error
    err.raise_mysql_exception(self._data)
  File "/usr/local/lib/python3.6/site-packages/pymysql/err.py", line 143, in raise_mysql_exception
    raise errorclass(errno, errval)
sqlalchemy.exc.OperationalError: (pymysql.err.OperationalError) (1050, "Table 'DimTorrent' already exists")
[SQL: 
CREATE TABLE `DimTorrent` (
	torrent_id BIGINT, 
	url_torrent TEXT, 
	size TEXT, 
	size_bytes BIGINT, 
	type TEXT, 
	quality TEXT, 
	language TEXT, 
	uploaded_torrent_at DATETIME, 
	created_at TIMESTAMP NULL, 
	updated_at TIMESTAMP NULL, 
	loaded_at TIMESTAMP NULL, 
	loaded_by TEXT
)

]
(Background on this error at: http://sqlalche.me/e/13/e3q8)

During handling of the above exception, another exception occurred:

Traceback (most recent call last):
  File "/home/airflow/.local/lib/python3.6/site-packages/airflow/models/taskinstance.py", line 1324, in _run_raw_task
    self._execute_task_with_callbacks(context)
  File "/home/airflow/.local/lib/python3.6/site-packages/airflow/models/taskinstance.py", line 1443, in _execute_task_with_callbacks
    result = self._execute_task(context, self.task)
  File "/home/airflow/.local/lib/python3.6/site-packages/airflow/models/taskinstance.py", line 1494, in _execute_task
    result = execute_callable(context=context)
  File "/home/airflow/.local/lib/python3.6/site-packages/airflow/operators/python.py", line 151, in execute
    return_value = self.execute_callable()
  File "/home/airflow/.local/lib/python3.6/site-packages/airflow/operators/python.py", line 162, in execute_callable
    return self.python_callable(*self.op_args, **self.op_kwargs)
  File "/opt/airflow/dags/ETL/load.py", line 68, in LoadStartSchema
    raise TypeError(e)
TypeError: (pymysql.err.OperationalError) (1050, "Table 'DimTorrent' already exists")
[SQL: 
CREATE TABLE `DimTorrent` (
	torrent_id BIGINT, 
	url_torrent TEXT, 
	size TEXT, 
	size_bytes BIGINT, 
	type TEXT, 
	quality TEXT, 
	language TEXT, 
	uploaded_torrent_at DATETIME, 
	created_at TIMESTAMP NULL, 
	updated_at TIMESTAMP NULL, 
	loaded_at TIMESTAMP NULL, 
	loaded_by TEXT
)

]
(Background on this error at: http://sqlalche.me/e/13/e3q8)
[2022-05-15 19:43:20,803] {taskinstance.py:1280} INFO - Marking task as UP_FOR_RETRY. dag_id=orchestrator, task_id=load_data, execution_date=20220515T194255, start_date=20220515T194318, end_date=20220515T194320
[2022-05-15 19:43:20,878] {standard_task_runner.py:91} ERROR - Failed to execute job 56 for task load_data
Traceback (most recent call last):
  File "/home/airflow/.local/lib/python3.6/site-packages/sqlalchemy/engine/base.py", line 1277, in _execute_context
    cursor, statement, parameters, context
  File "/home/airflow/.local/lib/python3.6/site-packages/sqlalchemy/engine/default.py", line 608, in do_execute
    cursor.execute(statement, parameters)
  File "/usr/local/lib/python3.6/site-packages/pymysql/cursors.py", line 148, in execute
    result = self._query(query)
  File "/usr/local/lib/python3.6/site-packages/pymysql/cursors.py", line 310, in _query
    conn.query(q)
  File "/usr/local/lib/python3.6/site-packages/pymysql/connections.py", line 548, in query
    self._affected_rows = self._read_query_result(unbuffered=unbuffered)
  File "/usr/local/lib/python3.6/site-packages/pymysql/connections.py", line 775, in _read_query_result
    result.read()
  File "/usr/local/lib/python3.6/site-packages/pymysql/connections.py", line 1156, in read
    first_packet = self.connection._read_packet()
  File "/usr/local/lib/python3.6/site-packages/pymysql/connections.py", line 725, in _read_packet
    packet.raise_for_error()
  File "/usr/local/lib/python3.6/site-packages/pymysql/protocol.py", line 221, in raise_for_error
    err.raise_mysql_exception(self._data)
  File "/usr/local/lib/python3.6/site-packages/pymysql/err.py", line 143, in raise_mysql_exception
    raise errorclass(errno, errval)
pymysql.err.OperationalError: (1050, "Table 'DimTorrent' already exists")

The above exception was the direct cause of the following exception:

Traceback (most recent call last):
  File "/opt/airflow/dags/ETL/load.py", line 57, in LoadStartSchema
    df_torrent.to_sql('DimTorrent',dbcon_write,if_exists='replace',index=False)
  File "/home/airflow/.local/lib/python3.6/site-packages/pandas/core/generic.py", line 2615, in to_sql
    method=method,
  File "/home/airflow/.local/lib/python3.6/site-packages/pandas/io/sql.py", line 598, in to_sql
    method=method,
  File "/home/airflow/.local/lib/python3.6/site-packages/pandas/io/sql.py", line 1393, in to_sql
    table.create()
  File "/home/airflow/.local/lib/python3.6/site-packages/pandas/io/sql.py", line 732, in create
    self._execute_create()
  File "/home/airflow/.local/lib/python3.6/site-packages/pandas/io/sql.py", line 718, in _execute_create
    self.table.create()
  File "/home/airflow/.local/lib/python3.6/site-packages/sqlalchemy/sql/schema.py", line 928, in create
    bind._run_visitor(ddl.SchemaGenerator, self, checkfirst=checkfirst)
  File "/home/airflow/.local/lib/python3.6/site-packages/sqlalchemy/engine/base.py", line 2095, in _run_visitor
    conn._run_visitor(visitorcallable, element, **kwargs)
  File "/home/airflow/.local/lib/python3.6/site-packages/sqlalchemy/engine/base.py", line 1656, in _run_visitor
    visitorcallable(self.dialect, self, **kwargs).traverse_single(element)
  File "/home/airflow/.local/lib/python3.6/site-packages/sqlalchemy/sql/visitors.py", line 145, in traverse_single
    return meth(obj, **kw)
  File "/home/airflow/.local/lib/python3.6/site-packages/sqlalchemy/sql/ddl.py", line 832, in visit_table
    include_foreign_key_constraints,  # noqa
  File "/home/airflow/.local/lib/python3.6/site-packages/sqlalchemy/engine/base.py", line 1011, in execute
    return meth(self, multiparams, params)
  File "/home/airflow/.local/lib/python3.6/site-packages/sqlalchemy/sql/ddl.py", line 72, in _execute_on_connection
    return connection._execute_ddl(self, multiparams, params)
  File "/home/airflow/.local/lib/python3.6/site-packages/sqlalchemy/engine/base.py", line 1073, in _execute_ddl
    compiled,
  File "/home/airflow/.local/lib/python3.6/site-packages/sqlalchemy/engine/base.py", line 1317, in _execute_context
    e, statement, parameters, cursor, context
  File "/home/airflow/.local/lib/python3.6/site-packages/sqlalchemy/engine/base.py", line 1511, in _handle_dbapi_exception
    sqlalchemy_exception, with_traceback=exc_info[2], from_=e
  File "/home/airflow/.local/lib/python3.6/site-packages/sqlalchemy/util/compat.py", line 182, in raise_
    raise exception
  File "/home/airflow/.local/lib/python3.6/site-packages/sqlalchemy/engine/base.py", line 1277, in _execute_context
    cursor, statement, parameters, context
  File "/home/airflow/.local/lib/python3.6/site-packages/sqlalchemy/engine/default.py", line 608, in do_execute
    cursor.execute(statement, parameters)
  File "/usr/local/lib/python3.6/site-packages/pymysql/cursors.py", line 148, in execute
    result = self._query(query)
  File "/usr/local/lib/python3.6/site-packages/pymysql/cursors.py", line 310, in _query
    conn.query(q)
  File "/usr/local/lib/python3.6/site-packages/pymysql/connections.py", line 548, in query
    self._affected_rows = self._read_query_result(unbuffered=unbuffered)
  File "/usr/local/lib/python3.6/site-packages/pymysql/connections.py", line 775, in _read_query_result
    result.read()
  File "/usr/local/lib/python3.6/site-packages/pymysql/connections.py", line 1156, in read
    first_packet = self.connection._read_packet()
  File "/usr/local/lib/python3.6/site-packages/pymysql/connections.py", line 725, in _read_packet
    packet.raise_for_error()
  File "/usr/local/lib/python3.6/site-packages/pymysql/protocol.py", line 221, in raise_for_error
    err.raise_mysql_exception(self._data)
  File "/usr/local/lib/python3.6/site-packages/pymysql/err.py", line 143, in raise_mysql_exception
    raise errorclass(errno, errval)
sqlalchemy.exc.OperationalError: (pymysql.err.OperationalError) (1050, "Table 'DimTorrent' already exists")
[SQL: 
CREATE TABLE `DimTorrent` (
	torrent_id BIGINT, 
	url_torrent TEXT, 
	size TEXT, 
	size_bytes BIGINT, 
	type TEXT, 
	quality TEXT, 
	language TEXT, 
	uploaded_torrent_at DATETIME, 
	created_at TIMESTAMP NULL, 
	updated_at TIMESTAMP NULL, 
	loaded_at TIMESTAMP NULL, 
	loaded_by TEXT
)

]
(Background on this error at: http://sqlalche.me/e/13/e3q8)

During handling of the above exception, another exception occurred:

Traceback (most recent call last):
  File "/home/airflow/.local/lib/python3.6/site-packages/airflow/task/task_runner/standard_task_runner.py", line 85, in _start_by_fork
    args.func(args, dag=self.dag)
  File "/home/airflow/.local/lib/python3.6/site-packages/airflow/cli/cli_parser.py", line 48, in command
    return func(*args, **kwargs)
  File "/home/airflow/.local/lib/python3.6/site-packages/airflow/utils/cli.py", line 92, in wrapper
    return f(*args, **kwargs)
  File "/home/airflow/.local/lib/python3.6/site-packages/airflow/cli/commands/task_command.py", line 292, in task_run
    _run_task_by_selected_method(args, dag, ti)
  File "/home/airflow/.local/lib/python3.6/site-packages/airflow/cli/commands/task_command.py", line 107, in _run_task_by_selected_method
    _run_raw_task(args, ti)
  File "/home/airflow/.local/lib/python3.6/site-packages/airflow/cli/commands/task_command.py", line 184, in _run_raw_task
    error_file=args.error_file,
  File "/home/airflow/.local/lib/python3.6/site-packages/airflow/utils/session.py", line 70, in wrapper
    return func(*args, session=session, **kwargs)
  File "/home/airflow/.local/lib/python3.6/site-packages/airflow/models/taskinstance.py", line 1324, in _run_raw_task
    self._execute_task_with_callbacks(context)
  File "/home/airflow/.local/lib/python3.6/site-packages/airflow/models/taskinstance.py", line 1443, in _execute_task_with_callbacks
    result = self._execute_task(context, self.task)
  File "/home/airflow/.local/lib/python3.6/site-packages/airflow/models/taskinstance.py", line 1494, in _execute_task
    result = execute_callable(context=context)
  File "/home/airflow/.local/lib/python3.6/site-packages/airflow/operators/python.py", line 151, in execute
    return_value = self.execute_callable()
  File "/home/airflow/.local/lib/python3.6/site-packages/airflow/operators/python.py", line 162, in execute_callable
    return self.python_callable(*self.op_args, **self.op_kwargs)
  File "/opt/airflow/dags/ETL/load.py", line 68, in LoadStartSchema
    raise TypeError(e)
TypeError: (pymysql.err.OperationalError) (1050, "Table 'DimTorrent' already exists")
[SQL: 
CREATE TABLE `DimTorrent` (
	torrent_id BIGINT, 
	url_torrent TEXT, 
	size TEXT, 
	size_bytes BIGINT, 
	type TEXT, 
	quality TEXT, 
	language TEXT, 
	uploaded_torrent_at DATETIME, 
	created_at TIMESTAMP NULL, 
	updated_at TIMESTAMP NULL, 
	loaded_at TIMESTAMP NULL, 
	loaded_by TEXT
)

]
(Background on this error at: http://sqlalche.me/e/13/e3q8)
[2022-05-15 19:43:20,906] {local_task_job.py:154} INFO - Task exited with return code 1
[2022-05-15 19:43:21,016] {local_task_job.py:264} INFO - 0 downstream tasks scheduled from follow-on schedule check
[2022-05-15 19:43:24,606] {base.py:79} INFO - Using connection to: id: MySql Localhost. Host: 192.168.15.14, Port: 3306, Schema: , Login: db_user, Password: ***, extra: {}
[2022-05-15 19:43:24,744] {load.py:62} INFO - Insert lines in Dim Torrent 1999
[2022-05-15 19:43:24,745] {load.py:63} INFO - Completed creation Dim Torrent
[2022-05-15 19:43:24,745] {load.py:74} INFO - Creating Dim Genres
[2022-05-15 19:43:24,778] {base.py:79} INFO - Using connection to: id: MySql Localhost. Host: 192.168.15.14, Port: 3306, Schema: , Login: db_user, Password: ***, extra: {}
[2022-05-15 19:43:26,366] {base.py:79} INFO - Using connection to: id: MySql Localhost. Host: 192.168.15.14, Port: 3306, Schema: , Login: db_user, Password: ***, extra: {}
[2022-05-15 19:43:26,490] {load.py:95} INFO - Insert lines in Dim Genres 223
[2022-05-15 19:43:26,490] {load.py:96} INFO - Completed creation Dim Genres
[2022-05-15 19:43:26,490] {load.py:107} INFO - Creating Fat Movies
[2022-05-15 19:43:26,522] {base.py:79} INFO - Using connection to: id: MySql Localhost. Host: 192.168.15.14, Port: 3306, Schema: , Login: db_user, Password: ***, extra: {}
[2022-05-15 19:43:33,044] {base.py:79} INFO - Using connection to: id: MySql Localhost. Host: 192.168.15.14, Port: 3306, Schema: , Login: db_user, Password: ***, extra: {}
[2022-05-15 19:43:33,187] {load.py:129} INFO - Insert lines in Fat Movies 1999
[2022-05-15 19:43:33,187] {load.py:130} INFO - Completed creation Fat Movies
[2022-05-15 19:43:33,187] {load.py:138} INFO - Completed process load start schema
[2022-05-15 19:43:33,190] {python.py:152} INFO - Done. Returned value was: None
[2022-05-15 19:43:33,227] {taskinstance.py:1280} INFO - Marking task as SUCCESS. dag_id=orchestrator, task_id=load_data, execution_date=20220514T000000, start_date=20220515T194318, end_date=20220515T194333
[2022-05-15 19:43:33,334] {local_task_job.py:154} INFO - Task exited with return code 0
[2022-05-15 19:43:33,444] {local_task_job.py:264} INFO - 0 downstream tasks scheduled from follow-on schedule check
[2022-05-15 19:47:40,280] {taskinstance.py:1035} INFO - Dependencies all met for <TaskInstance: orchestrator.load_data manual__2022-05-15T19:47:12.935448+00:00 [queued]>
[2022-05-15 19:47:40,319] {taskinstance.py:1035} INFO - Dependencies all met for <TaskInstance: orchestrator.load_data manual__2022-05-15T19:47:12.935448+00:00 [queued]>
[2022-05-15 19:47:40,319] {taskinstance.py:1241} INFO - 
--------------------------------------------------------------------------------
[2022-05-15 19:47:40,319] {taskinstance.py:1242} INFO - Starting attempt 1 of 2
[2022-05-15 19:47:40,319] {taskinstance.py:1243} INFO - 
--------------------------------------------------------------------------------
[2022-05-15 19:47:40,386] {taskinstance.py:1262} INFO - Executing <Task(PythonOperator): load_data> on 2022-05-15 19:47:12.935448+00:00
[2022-05-15 19:47:40,391] {standard_task_runner.py:52} INFO - Started process 1425 to run task
[2022-05-15 19:47:40,395] {standard_task_runner.py:76} INFO - Running: ['***', 'tasks', 'run', 'orchestrator', 'load_data', 'manual__2022-05-15T19:47:12.935448+00:00', '--job-id', '63', '--raw', '--subdir', 'DAGS_FOLDER/pipeline.py', '--cfg-path', '/tmp/tmpwv67xjeo', '--error-file', '/tmp/tmp58jl21_x']
[2022-05-15 19:47:40,395] {standard_task_runner.py:77} INFO - Job 63: Subtask load_data
[2022-05-15 19:47:40,467] {logging_mixin.py:109} INFO - Running <TaskInstance: orchestrator.load_data manual__2022-05-15T19:47:12.935448+00:00 [running]> on host 87efc59194bd
[2022-05-15 19:47:40,686] {taskinstance.py:1414} INFO - Exporting the following env vars:
AIRFLOW_CTX_DAG_EMAIL=***@example.com
AIRFLOW_CTX_DAG_OWNER=***
AIRFLOW_CTX_DAG_ID=orchestrator
AIRFLOW_CTX_TASK_ID=load_data
AIRFLOW_CTX_EXECUTION_DATE=2022-05-15T19:47:12.935448+00:00
AIRFLOW_CTX_DAG_RUN_ID=manual__2022-05-15T19:47:12.935448+00:00
[2022-05-15 19:47:40,686] {load.py:17} INFO - Starting process load star schema
[2022-05-15 19:47:40,707] {base.py:79} INFO - Using connection to: id: MySql Localhost. Host: 192.168.15.14, Port: 3306, Schema: , Login: db_user, Password: ***, extra: {}
[2022-05-15 19:47:41,138] {load.py:39} INFO - Creating Dim Torrent
[2022-05-15 19:47:41,154] {base.py:79} INFO - Using connection to: id: MySql Localhost. Host: 192.168.15.14, Port: 3306, Schema: , Login: db_user, Password: ***, extra: {}
[2022-05-15 19:47:44,306] {taskinstance.py:1035} INFO - Dependencies all met for <TaskInstance: orchestrator.load_data scheduled__2022-05-14T00:00:00+00:00 [queued]>
[2022-05-15 19:47:44,368] {taskinstance.py:1035} INFO - Dependencies all met for <TaskInstance: orchestrator.load_data scheduled__2022-05-14T00:00:00+00:00 [queued]>
[2022-05-15 19:47:44,369] {taskinstance.py:1241} INFO - 
--------------------------------------------------------------------------------
[2022-05-15 19:47:44,369] {taskinstance.py:1242} INFO - Starting attempt 1 of 2
[2022-05-15 19:47:44,369] {taskinstance.py:1243} INFO - 
--------------------------------------------------------------------------------
[2022-05-15 19:47:44,435] {taskinstance.py:1262} INFO - Executing <Task(PythonOperator): load_data> on 2022-05-14 00:00:00+00:00
[2022-05-15 19:47:44,440] {standard_task_runner.py:52} INFO - Started process 1427 to run task
[2022-05-15 19:47:44,443] {standard_task_runner.py:76} INFO - Running: ['***', 'tasks', 'run', 'orchestrator', 'load_data', 'scheduled__2022-05-14T00:00:00+00:00', '--job-id', '64', '--raw', '--subdir', 'DAGS_FOLDER/pipeline.py', '--cfg-path', '/tmp/tmp9w76g8hj', '--error-file', '/tmp/tmpc04hwfu8']
[2022-05-15 19:47:44,444] {standard_task_runner.py:77} INFO - Job 64: Subtask load_data
[2022-05-15 19:47:44,600] {logging_mixin.py:109} INFO - Running <TaskInstance: orchestrator.load_data scheduled__2022-05-14T00:00:00+00:00 [running]> on host 87efc59194bd
[2022-05-15 19:47:44,735] {taskinstance.py:1414} INFO - Exporting the following env vars:
AIRFLOW_CTX_DAG_EMAIL=***@example.com
AIRFLOW_CTX_DAG_OWNER=***
AIRFLOW_CTX_DAG_ID=orchestrator
AIRFLOW_CTX_TASK_ID=load_data
AIRFLOW_CTX_EXECUTION_DATE=2022-05-14T00:00:00+00:00
AIRFLOW_CTX_DAG_RUN_ID=scheduled__2022-05-14T00:00:00+00:00
[2022-05-15 19:47:44,736] {load.py:17} INFO - Starting process load star schema
[2022-05-15 19:47:44,753] {base.py:79} INFO - Using connection to: id: MySql Localhost. Host: 192.168.15.14, Port: 3306, Schema: , Login: db_user, Password: ***, extra: {}
[2022-05-15 19:47:45,206] {load.py:39} INFO - Creating Dim Torrent
[2022-05-15 19:47:45,222] {base.py:79} INFO - Using connection to: id: MySql Localhost. Host: 192.168.15.14, Port: 3306, Schema: , Login: db_user, Password: ***, extra: {}
[2022-05-15 19:47:47,296] {base.py:79} INFO - Using connection to: id: MySql Localhost. Host: 192.168.15.14, Port: 3306, Schema: , Login: db_user, Password: ***, extra: {}
[2022-05-15 19:47:47,489] {load.py:62} INFO - Insert lines in Dim Torrent 2025
[2022-05-15 19:47:47,490] {load.py:63} INFO - Completed creation Dim Torrent
[2022-05-15 19:47:47,490] {load.py:74} INFO - Creating Dim Genres
[2022-05-15 19:47:47,506] {base.py:79} INFO - Using connection to: id: MySql Localhost. Host: 192.168.15.14, Port: 3306, Schema: , Login: db_user, Password: ***, extra: {}
[2022-05-15 19:47:49,600] {base.py:79} INFO - Using connection to: id: MySql Localhost. Host: 192.168.15.14, Port: 3306, Schema: , Login: db_user, Password: ***, extra: {}
[2022-05-15 19:47:49,924] {load.py:95} INFO - Insert lines in Dim Genres 223
[2022-05-15 19:47:49,925] {load.py:96} INFO - Completed creation Dim Genres
[2022-05-15 19:47:49,925] {load.py:107} INFO - Creating Fat Movies
[2022-05-15 19:47:49,953] {base.py:79} INFO - Using connection to: id: MySql Localhost. Host: 192.168.15.14, Port: 3306, Schema: , Login: db_user, Password: ***, extra: {}
[2022-05-15 19:47:50,705] {local_task_job.py:212} WARNING - State of this instance has been externally set to None. Terminating instance.
[2022-05-15 19:47:50,707] {process_utils.py:100} INFO - Sending Signals.SIGTERM to GPID 1425
[2022-05-15 19:47:50,707] {taskinstance.py:1396} ERROR - Received SIGTERM. Terminating subprocesses.
[2022-05-15 19:47:50,746] {load.py:133} ERROR - Error to load start schema: (pymysql.err.InterfaceError) (0, '')
(Background on this error at: http://sqlalche.me/e/13/rvf5)
[2022-05-15 19:47:50,764] {base.py:79} INFO - Using connection to: id: MySql Localhost. Host: 192.168.15.14, Port: 3306, Schema: , Login: db_user, Password: ***, extra: {}
[2022-05-15 19:47:51,237] {load.py:138} INFO - Completed process load start schema
[2022-05-15 19:47:51,237] {taskinstance.py:1686} ERROR - Task failed with exception
Traceback (most recent call last):
  File "/home/airflow/.local/lib/python3.6/site-packages/sqlalchemy/engine/base.py", line 1277, in _execute_context
    cursor, statement, parameters, context
  File "/home/airflow/.local/lib/python3.6/site-packages/sqlalchemy/engine/default.py", line 608, in do_execute
    cursor.execute(statement, parameters)
  File "/usr/local/lib/python3.6/site-packages/pymysql/cursors.py", line 148, in execute
    result = self._query(query)
  File "/usr/local/lib/python3.6/site-packages/pymysql/cursors.py", line 310, in _query
    conn.query(q)
  File "/usr/local/lib/python3.6/site-packages/pymysql/connections.py", line 548, in query
    self._affected_rows = self._read_query_result(unbuffered=unbuffered)
  File "/usr/local/lib/python3.6/site-packages/pymysql/connections.py", line 775, in _read_query_result
    result.read()
  File "/usr/local/lib/python3.6/site-packages/pymysql/connections.py", line 1156, in read
    first_packet = self.connection._read_packet()
  File "/usr/local/lib/python3.6/site-packages/pymysql/connections.py", line 692, in _read_packet
    packet_header = self._read_bytes(4)
  File "/usr/local/lib/python3.6/site-packages/pymysql/connections.py", line 732, in _read_bytes
    data = self._rfile.read(num_bytes)
  File "/usr/local/lib/python3.6/socket.py", line 586, in readinto
    return self._sock.recv_into(b)
  File "/home/airflow/.local/lib/python3.6/site-packages/airflow/models/taskinstance.py", line 1398, in signal_handler
    raise AirflowException("Task received SIGTERM signal")
airflow.exceptions.AirflowException: Task received SIGTERM signal

During handling of the above exception, another exception occurred:

Traceback (most recent call last):
  File "/home/airflow/.local/lib/python3.6/site-packages/sqlalchemy/engine/base.py", line 749, in _rollback_impl
    self.engine.dialect.do_rollback(self.connection)
  File "/home/airflow/.local/lib/python3.6/site-packages/sqlalchemy/dialects/mysql/base.py", line 2513, in do_rollback
    dbapi_connection.rollback()
  File "/usr/local/lib/python3.6/site-packages/pymysql/connections.py", line 479, in rollback
    self._execute_command(COMMAND.COM_QUERY, "ROLLBACK")
  File "/usr/local/lib/python3.6/site-packages/pymysql/connections.py", line 793, in _execute_command
    raise err.InterfaceError(0, "")
pymysql.err.InterfaceError: (0, '')

The above exception was the direct cause of the following exception:

Traceback (most recent call last):
  File "/opt/airflow/dags/ETL/load.py", line 124, in LoadStartSchema
    df_fat.to_sql('FatMovies',dbcon_write,if_exists='replace',index=False)
  File "/home/airflow/.local/lib/python3.6/site-packages/pandas/core/generic.py", line 2615, in to_sql
    method=method,
  File "/home/airflow/.local/lib/python3.6/site-packages/pandas/io/sql.py", line 598, in to_sql
    method=method,
  File "/home/airflow/.local/lib/python3.6/site-packages/pandas/io/sql.py", line 1393, in to_sql
    table.create()
  File "/home/airflow/.local/lib/python3.6/site-packages/pandas/io/sql.py", line 725, in create
    self.pd_sql.drop_table(self.name, self.schema)
  File "/home/airflow/.local/lib/python3.6/site-packages/pandas/io/sql.py", line 1454, in drop_table
    self.get_table(table_name, schema).drop()
  File "/home/airflow/.local/lib/python3.6/site-packages/sqlalchemy/sql/schema.py", line 942, in drop
    bind._run_visitor(ddl.SchemaDropper, self, checkfirst=checkfirst)
  File "/home/airflow/.local/lib/python3.6/site-packages/sqlalchemy/engine/base.py", line 2095, in _run_visitor
    conn._run_visitor(visitorcallable, element, **kwargs)
  File "/home/airflow/.local/lib/python3.6/site-packages/sqlalchemy/engine/base.py", line 1656, in _run_visitor
    visitorcallable(self.dialect, self, **kwargs).traverse_single(element)
  File "/home/airflow/.local/lib/python3.6/site-packages/sqlalchemy/sql/visitors.py", line 145, in traverse_single
    return meth(obj, **kw)
  File "/home/airflow/.local/lib/python3.6/site-packages/sqlalchemy/sql/ddl.py", line 1018, in visit_table
    self.connection.execute(DropTable(table))
  File "/home/airflow/.local/lib/python3.6/site-packages/sqlalchemy/engine/base.py", line 1011, in execute
    return meth(self, multiparams, params)
  File "/home/airflow/.local/lib/python3.6/site-packages/sqlalchemy/sql/ddl.py", line 72, in _execute_on_connection
    return connection._execute_ddl(self, multiparams, params)
  File "/home/airflow/.local/lib/python3.6/site-packages/sqlalchemy/engine/base.py", line 1073, in _execute_ddl
    compiled,
  File "/home/airflow/.local/lib/python3.6/site-packages/sqlalchemy/engine/base.py", line 1317, in _execute_context
    e, statement, parameters, cursor, context
  File "/home/airflow/.local/lib/python3.6/site-packages/sqlalchemy/engine/base.py", line 1505, in _handle_dbapi_exception
    self._autorollback()
  File "/home/airflow/.local/lib/python3.6/site-packages/sqlalchemy/util/langhelpers.py", line 82, in __exit__
    compat.raise_(value, with_traceback=traceback)
  File "/home/airflow/.local/lib/python3.6/site-packages/sqlalchemy/util/compat.py", line 182, in raise_
    raise exception
  File "/home/airflow/.local/lib/python3.6/site-packages/sqlalchemy/engine/base.py", line 1505, in _handle_dbapi_exception
    self._autorollback()
  File "/home/airflow/.local/lib/python3.6/site-packages/sqlalchemy/engine/base.py", line 888, in _autorollback
    self._root._rollback_impl()
  File "/home/airflow/.local/lib/python3.6/site-packages/sqlalchemy/engine/base.py", line 751, in _rollback_impl
    self._handle_dbapi_exception(e, None, None, None, None)
  File "/home/airflow/.local/lib/python3.6/site-packages/sqlalchemy/engine/base.py", line 1418, in _handle_dbapi_exception
    from_=e,
  File "/home/airflow/.local/lib/python3.6/site-packages/sqlalchemy/util/compat.py", line 182, in raise_
    raise exception
  File "/home/airflow/.local/lib/python3.6/site-packages/sqlalchemy/engine/base.py", line 749, in _rollback_impl
    self.engine.dialect.do_rollback(self.connection)
  File "/home/airflow/.local/lib/python3.6/site-packages/sqlalchemy/dialects/mysql/base.py", line 2513, in do_rollback
    dbapi_connection.rollback()
  File "/usr/local/lib/python3.6/site-packages/pymysql/connections.py", line 479, in rollback
    self._execute_command(COMMAND.COM_QUERY, "ROLLBACK")
  File "/usr/local/lib/python3.6/site-packages/pymysql/connections.py", line 793, in _execute_command
    raise err.InterfaceError(0, "")
sqlalchemy.exc.InterfaceError: (pymysql.err.InterfaceError) (0, '')
(Background on this error at: http://sqlalche.me/e/13/rvf5)

During handling of the above exception, another exception occurred:

Traceback (most recent call last):
  File "/home/airflow/.local/lib/python3.6/site-packages/airflow/models/taskinstance.py", line 1324, in _run_raw_task
    self._execute_task_with_callbacks(context)
  File "/home/airflow/.local/lib/python3.6/site-packages/airflow/models/taskinstance.py", line 1443, in _execute_task_with_callbacks
    result = self._execute_task(context, self.task)
  File "/home/airflow/.local/lib/python3.6/site-packages/airflow/models/taskinstance.py", line 1494, in _execute_task
    result = execute_callable(context=context)
  File "/home/airflow/.local/lib/python3.6/site-packages/airflow/operators/python.py", line 151, in execute
    return_value = self.execute_callable()
  File "/home/airflow/.local/lib/python3.6/site-packages/airflow/operators/python.py", line 162, in execute_callable
    return self.python_callable(*self.op_args, **self.op_kwargs)
  File "/opt/airflow/dags/ETL/load.py", line 135, in LoadStartSchema
    raise TypeError(e)
TypeError: (pymysql.err.InterfaceError) (0, '')
(Background on this error at: http://sqlalche.me/e/13/rvf5)
[2022-05-15 19:47:51,274] {taskinstance.py:1280} INFO - Marking task as FAILED. dag_id=orchestrator, task_id=load_data, execution_date=20220515T194712, start_date=20220515T194740, end_date=20220515T194751
[2022-05-15 19:47:51,344] {standard_task_runner.py:91} ERROR - Failed to execute job 63 for task load_data
Traceback (most recent call last):
  File "/home/airflow/.local/lib/python3.6/site-packages/sqlalchemy/engine/base.py", line 1277, in _execute_context
    cursor, statement, parameters, context
  File "/home/airflow/.local/lib/python3.6/site-packages/sqlalchemy/engine/default.py", line 608, in do_execute
    cursor.execute(statement, parameters)
  File "/usr/local/lib/python3.6/site-packages/pymysql/cursors.py", line 148, in execute
    result = self._query(query)
  File "/usr/local/lib/python3.6/site-packages/pymysql/cursors.py", line 310, in _query
    conn.query(q)
  File "/usr/local/lib/python3.6/site-packages/pymysql/connections.py", line 548, in query
    self._affected_rows = self._read_query_result(unbuffered=unbuffered)
  File "/usr/local/lib/python3.6/site-packages/pymysql/connections.py", line 775, in _read_query_result
    result.read()
  File "/usr/local/lib/python3.6/site-packages/pymysql/connections.py", line 1156, in read
    first_packet = self.connection._read_packet()
  File "/usr/local/lib/python3.6/site-packages/pymysql/connections.py", line 692, in _read_packet
    packet_header = self._read_bytes(4)
  File "/usr/local/lib/python3.6/site-packages/pymysql/connections.py", line 732, in _read_bytes
    data = self._rfile.read(num_bytes)
  File "/usr/local/lib/python3.6/socket.py", line 586, in readinto
    return self._sock.recv_into(b)
  File "/home/airflow/.local/lib/python3.6/site-packages/airflow/models/taskinstance.py", line 1398, in signal_handler
    raise AirflowException("Task received SIGTERM signal")
airflow.exceptions.AirflowException: Task received SIGTERM signal

During handling of the above exception, another exception occurred:

Traceback (most recent call last):
  File "/home/airflow/.local/lib/python3.6/site-packages/sqlalchemy/engine/base.py", line 749, in _rollback_impl
    self.engine.dialect.do_rollback(self.connection)
  File "/home/airflow/.local/lib/python3.6/site-packages/sqlalchemy/dialects/mysql/base.py", line 2513, in do_rollback
    dbapi_connection.rollback()
  File "/usr/local/lib/python3.6/site-packages/pymysql/connections.py", line 479, in rollback
    self._execute_command(COMMAND.COM_QUERY, "ROLLBACK")
  File "/usr/local/lib/python3.6/site-packages/pymysql/connections.py", line 793, in _execute_command
    raise err.InterfaceError(0, "")
pymysql.err.InterfaceError: (0, '')

The above exception was the direct cause of the following exception:

Traceback (most recent call last):
  File "/opt/airflow/dags/ETL/load.py", line 124, in LoadStartSchema
    df_fat.to_sql('FatMovies',dbcon_write,if_exists='replace',index=False)
  File "/home/airflow/.local/lib/python3.6/site-packages/pandas/core/generic.py", line 2615, in to_sql
    method=method,
  File "/home/airflow/.local/lib/python3.6/site-packages/pandas/io/sql.py", line 598, in to_sql
    method=method,
  File "/home/airflow/.local/lib/python3.6/site-packages/pandas/io/sql.py", line 1393, in to_sql
    table.create()
  File "/home/airflow/.local/lib/python3.6/site-packages/pandas/io/sql.py", line 725, in create
    self.pd_sql.drop_table(self.name, self.schema)
  File "/home/airflow/.local/lib/python3.6/site-packages/pandas/io/sql.py", line 1454, in drop_table
    self.get_table(table_name, schema).drop()
  File "/home/airflow/.local/lib/python3.6/site-packages/sqlalchemy/sql/schema.py", line 942, in drop
    bind._run_visitor(ddl.SchemaDropper, self, checkfirst=checkfirst)
  File "/home/airflow/.local/lib/python3.6/site-packages/sqlalchemy/engine/base.py", line 2095, in _run_visitor
    conn._run_visitor(visitorcallable, element, **kwargs)
  File "/home/airflow/.local/lib/python3.6/site-packages/sqlalchemy/engine/base.py", line 1656, in _run_visitor
    visitorcallable(self.dialect, self, **kwargs).traverse_single(element)
  File "/home/airflow/.local/lib/python3.6/site-packages/sqlalchemy/sql/visitors.py", line 145, in traverse_single
    return meth(obj, **kw)
  File "/home/airflow/.local/lib/python3.6/site-packages/sqlalchemy/sql/ddl.py", line 1018, in visit_table
    self.connection.execute(DropTable(table))
  File "/home/airflow/.local/lib/python3.6/site-packages/sqlalchemy/engine/base.py", line 1011, in execute
    return meth(self, multiparams, params)
  File "/home/airflow/.local/lib/python3.6/site-packages/sqlalchemy/sql/ddl.py", line 72, in _execute_on_connection
    return connection._execute_ddl(self, multiparams, params)
  File "/home/airflow/.local/lib/python3.6/site-packages/sqlalchemy/engine/base.py", line 1073, in _execute_ddl
    compiled,
  File "/home/airflow/.local/lib/python3.6/site-packages/sqlalchemy/engine/base.py", line 1317, in _execute_context
    e, statement, parameters, cursor, context
  File "/home/airflow/.local/lib/python3.6/site-packages/sqlalchemy/engine/base.py", line 1505, in _handle_dbapi_exception
    self._autorollback()
  File "/home/airflow/.local/lib/python3.6/site-packages/sqlalchemy/util/langhelpers.py", line 82, in __exit__
    compat.raise_(value, with_traceback=traceback)
  File "/home/airflow/.local/lib/python3.6/site-packages/sqlalchemy/util/compat.py", line 182, in raise_
    raise exception
  File "/home/airflow/.local/lib/python3.6/site-packages/sqlalchemy/engine/base.py", line 1505, in _handle_dbapi_exception
    self._autorollback()
  File "/home/airflow/.local/lib/python3.6/site-packages/sqlalchemy/engine/base.py", line 888, in _autorollback
    self._root._rollback_impl()
  File "/home/airflow/.local/lib/python3.6/site-packages/sqlalchemy/engine/base.py", line 751, in _rollback_impl
    self._handle_dbapi_exception(e, None, None, None, None)
  File "/home/airflow/.local/lib/python3.6/site-packages/sqlalchemy/engine/base.py", line 1418, in _handle_dbapi_exception
    from_=e,
  File "/home/airflow/.local/lib/python3.6/site-packages/sqlalchemy/util/compat.py", line 182, in raise_
    raise exception
  File "/home/airflow/.local/lib/python3.6/site-packages/sqlalchemy/engine/base.py", line 749, in _rollback_impl
    self.engine.dialect.do_rollback(self.connection)
  File "/home/airflow/.local/lib/python3.6/site-packages/sqlalchemy/dialects/mysql/base.py", line 2513, in do_rollback
    dbapi_connection.rollback()
  File "/usr/local/lib/python3.6/site-packages/pymysql/connections.py", line 479, in rollback
    self._execute_command(COMMAND.COM_QUERY, "ROLLBACK")
  File "/usr/local/lib/python3.6/site-packages/pymysql/connections.py", line 793, in _execute_command
    raise err.InterfaceError(0, "")
sqlalchemy.exc.InterfaceError: (pymysql.err.InterfaceError) (0, '')
(Background on this error at: http://sqlalche.me/e/13/rvf5)

During handling of the above exception, another exception occurred:

Traceback (most recent call last):
  File "/home/airflow/.local/lib/python3.6/site-packages/airflow/task/task_runner/standard_task_runner.py", line 85, in _start_by_fork
    args.func(args, dag=self.dag)
  File "/home/airflow/.local/lib/python3.6/site-packages/airflow/cli/cli_parser.py", line 48, in command
    return func(*args, **kwargs)
  File "/home/airflow/.local/lib/python3.6/site-packages/airflow/utils/cli.py", line 92, in wrapper
    return f(*args, **kwargs)
  File "/home/airflow/.local/lib/python3.6/site-packages/airflow/cli/commands/task_command.py", line 292, in task_run
    _run_task_by_selected_method(args, dag, ti)
  File "/home/airflow/.local/lib/python3.6/site-packages/airflow/cli/commands/task_command.py", line 107, in _run_task_by_selected_method
    _run_raw_task(args, ti)
  File "/home/airflow/.local/lib/python3.6/site-packages/airflow/cli/commands/task_command.py", line 184, in _run_raw_task
    error_file=args.error_file,
  File "/home/airflow/.local/lib/python3.6/site-packages/airflow/utils/session.py", line 70, in wrapper
    return func(*args, session=session, **kwargs)
  File "/home/airflow/.local/lib/python3.6/site-packages/airflow/models/taskinstance.py", line 1324, in _run_raw_task
    self._execute_task_with_callbacks(context)
  File "/home/airflow/.local/lib/python3.6/site-packages/airflow/models/taskinstance.py", line 1443, in _execute_task_with_callbacks
    result = self._execute_task(context, self.task)
  File "/home/airflow/.local/lib/python3.6/site-packages/airflow/models/taskinstance.py", line 1494, in _execute_task
    result = execute_callable(context=context)
  File "/home/airflow/.local/lib/python3.6/site-packages/airflow/operators/python.py", line 151, in execute
    return_value = self.execute_callable()
  File "/home/airflow/.local/lib/python3.6/site-packages/airflow/operators/python.py", line 162, in execute_callable
    return self.python_callable(*self.op_args, **self.op_kwargs)
  File "/opt/airflow/dags/ETL/load.py", line 135, in LoadStartSchema
    raise TypeError(e)
TypeError: (pymysql.err.InterfaceError) (0, '')
(Background on this error at: http://sqlalche.me/e/13/rvf5)
[2022-05-15 19:47:51,361] {process_utils.py:66} INFO - Process psutil.Process(pid=1425, status='terminated', exitcode=1, started='19:47:39') (1425) terminated with exit code 1
[2022-05-15 19:47:53,443] {base.py:79} INFO - Using connection to: id: MySql Localhost. Host: 192.168.15.14, Port: 3306, Schema: , Login: db_user, Password: ***, extra: {}
[2022-05-15 19:47:53,593] {load.py:62} INFO - Insert lines in Dim Torrent 2025
[2022-05-15 19:47:53,594] {load.py:63} INFO - Completed creation Dim Torrent
[2022-05-15 19:47:53,594] {load.py:74} INFO - Creating Dim Genres
[2022-05-15 19:47:53,623] {base.py:79} INFO - Using connection to: id: MySql Localhost. Host: 192.168.15.14, Port: 3306, Schema: , Login: db_user, Password: ***, extra: {}
[2022-05-15 19:47:55,291] {base.py:79} INFO - Using connection to: id: MySql Localhost. Host: 192.168.15.14, Port: 3306, Schema: , Login: db_user, Password: ***, extra: {}
[2022-05-15 19:47:55,439] {load.py:95} INFO - Insert lines in Dim Genres 223
[2022-05-15 19:47:55,440] {load.py:96} INFO - Completed creation Dim Genres
[2022-05-15 19:47:55,440] {load.py:107} INFO - Creating Fat Movies
[2022-05-15 19:47:55,475] {base.py:79} INFO - Using connection to: id: MySql Localhost. Host: 192.168.15.14, Port: 3306, Schema: , Login: db_user, Password: ***, extra: {}
[2022-05-15 19:47:59,916] {local_task_job.py:212} WARNING - State of this instance has been externally set to None. Terminating instance.
[2022-05-15 19:47:59,919] {process_utils.py:100} INFO - Sending Signals.SIGTERM to GPID 1427
[2022-05-15 19:47:59,919] {taskinstance.py:1396} ERROR - Received SIGTERM. Terminating subprocesses.
[2022-05-15 19:47:59,921] {load.py:133} ERROR - Error to load start schema: (pymysql.err.InterfaceError) (0, '')
(Background on this error at: http://sqlalche.me/e/13/rvf5)
[2022-05-15 19:47:59,942] {base.py:79} INFO - Using connection to: id: MySql Localhost. Host: 192.168.15.14, Port: 3306, Schema: , Login: db_user, Password: ***, extra: {}
[2022-05-15 19:48:00,229] {load.py:138} INFO - Completed process load start schema
[2022-05-15 19:48:00,230] {taskinstance.py:1686} ERROR - Task failed with exception
Traceback (most recent call last):
  File "/home/airflow/.local/lib/python3.6/site-packages/pandas/io/sql.py", line 1155, in run_transaction
    yield tx
  File "/home/airflow/.local/lib/python3.6/site-packages/pandas/io/sql.py", line 830, in insert
    exec_insert(conn, keys, chunk_iter)
  File "/home/airflow/.local/lib/python3.6/site-packages/pandas/io/sql.py", line 747, in _execute_insert
    conn.execute(self.table.insert(), data)
  File "/home/airflow/.local/lib/python3.6/site-packages/sqlalchemy/engine/base.py", line 1011, in execute
    return meth(self, multiparams, params)
  File "/home/airflow/.local/lib/python3.6/site-packages/sqlalchemy/sql/elements.py", line 298, in _execute_on_connection
    return connection._execute_clauseelement(self, multiparams, params)
  File "/home/airflow/.local/lib/python3.6/site-packages/sqlalchemy/engine/base.py", line 1130, in _execute_clauseelement
    distilled_params,
  File "/home/airflow/.local/lib/python3.6/site-packages/sqlalchemy/engine/base.py", line 1317, in _execute_context
    e, statement, parameters, cursor, context
  File "/home/airflow/.local/lib/python3.6/site-packages/sqlalchemy/engine/base.py", line 1514, in _handle_dbapi_exception
    util.raise_(exc_info[1], with_traceback=exc_info[2])
  File "/home/airflow/.local/lib/python3.6/site-packages/sqlalchemy/util/compat.py", line 182, in raise_
    raise exception
  File "/home/airflow/.local/lib/python3.6/site-packages/sqlalchemy/engine/base.py", line 1257, in _execute_context
    cursor, statement, parameters, context
  File "/home/airflow/.local/lib/python3.6/site-packages/sqlalchemy/dialects/mysql/mysqldb.py", line 148, in do_executemany
    rowcount = cursor.executemany(statement, parameters)
  File "/usr/local/lib/python3.6/site-packages/pymysql/cursors.py", line 179, in executemany
    self._get_db().encoding,
  File "/usr/local/lib/python3.6/site-packages/pymysql/cursors.py", line 206, in _do_execute_many
    rows += self.execute(sql + postfix)
  File "/usr/local/lib/python3.6/site-packages/pymysql/cursors.py", line 148, in execute
    result = self._query(query)
  File "/usr/local/lib/python3.6/site-packages/pymysql/cursors.py", line 310, in _query
    conn.query(q)
  File "/usr/local/lib/python3.6/site-packages/pymysql/connections.py", line 548, in query
    self._affected_rows = self._read_query_result(unbuffered=unbuffered)
  File "/usr/local/lib/python3.6/site-packages/pymysql/connections.py", line 775, in _read_query_result
    result.read()
  File "/usr/local/lib/python3.6/site-packages/pymysql/connections.py", line 1156, in read
    first_packet = self.connection._read_packet()
  File "/usr/local/lib/python3.6/site-packages/pymysql/connections.py", line 692, in _read_packet
    packet_header = self._read_bytes(4)
  File "/usr/local/lib/python3.6/site-packages/pymysql/connections.py", line 732, in _read_bytes
    data = self._rfile.read(num_bytes)
  File "/usr/local/lib/python3.6/socket.py", line 586, in readinto
    return self._sock.recv_into(b)
  File "/home/airflow/.local/lib/python3.6/site-packages/airflow/models/taskinstance.py", line 1398, in signal_handler
    raise AirflowException("Task received SIGTERM signal")
airflow.exceptions.AirflowException: Task received SIGTERM signal

During handling of the above exception, another exception occurred:

Traceback (most recent call last):
  File "/home/airflow/.local/lib/python3.6/site-packages/sqlalchemy/engine/base.py", line 749, in _rollback_impl
    self.engine.dialect.do_rollback(self.connection)
  File "/home/airflow/.local/lib/python3.6/site-packages/sqlalchemy/dialects/mysql/base.py", line 2513, in do_rollback
    dbapi_connection.rollback()
  File "/usr/local/lib/python3.6/site-packages/pymysql/connections.py", line 479, in rollback
    self._execute_command(COMMAND.COM_QUERY, "ROLLBACK")
  File "/usr/local/lib/python3.6/site-packages/pymysql/connections.py", line 793, in _execute_command
    raise err.InterfaceError(0, "")
pymysql.err.InterfaceError: (0, '')

The above exception was the direct cause of the following exception:

Traceback (most recent call last):
  File "/opt/airflow/dags/ETL/load.py", line 124, in LoadStartSchema
    df_fat.to_sql('FatMovies',dbcon_write,if_exists='replace',index=False)
  File "/home/airflow/.local/lib/python3.6/site-packages/pandas/core/generic.py", line 2615, in to_sql
    method=method,
  File "/home/airflow/.local/lib/python3.6/site-packages/pandas/io/sql.py", line 598, in to_sql
    method=method,
  File "/home/airflow/.local/lib/python3.6/site-packages/pandas/io/sql.py", line 1406, in to_sql
    raise err
  File "/home/airflow/.local/lib/python3.6/site-packages/pandas/io/sql.py", line 1398, in to_sql
    table.insert(chunksize, method=method)
  File "/home/airflow/.local/lib/python3.6/site-packages/pandas/io/sql.py", line 830, in insert
    exec_insert(conn, keys, chunk_iter)
  File "/usr/local/lib/python3.6/contextlib.py", line 99, in __exit__
    self.gen.throw(type, value, traceback)
  File "/home/airflow/.local/lib/python3.6/site-packages/pandas/io/sql.py", line 1157, in run_transaction
    yield self.connectable
  File "/home/airflow/.local/lib/python3.6/site-packages/sqlalchemy/engine/base.py", line 2108, in __exit__
    self.transaction.rollback()
  File "/home/airflow/.local/lib/python3.6/site-packages/sqlalchemy/engine/base.py", line 1751, in rollback
    self._do_rollback()
  File "/home/airflow/.local/lib/python3.6/site-packages/sqlalchemy/engine/base.py", line 1789, in _do_rollback
    self.connection._rollback_impl()
  File "/home/airflow/.local/lib/python3.6/site-packages/sqlalchemy/engine/base.py", line 751, in _rollback_impl
    self._handle_dbapi_exception(e, None, None, None, None)
  File "/home/airflow/.local/lib/python3.6/site-packages/sqlalchemy/engine/base.py", line 1511, in _handle_dbapi_exception
    sqlalchemy_exception, with_traceback=exc_info[2], from_=e
  File "/home/airflow/.local/lib/python3.6/site-packages/sqlalchemy/util/compat.py", line 182, in raise_
    raise exception
  File "/home/airflow/.local/lib/python3.6/site-packages/sqlalchemy/engine/base.py", line 749, in _rollback_impl
    self.engine.dialect.do_rollback(self.connection)
  File "/home/airflow/.local/lib/python3.6/site-packages/sqlalchemy/dialects/mysql/base.py", line 2513, in do_rollback
    dbapi_connection.rollback()
  File "/usr/local/lib/python3.6/site-packages/pymysql/connections.py", line 479, in rollback
    self._execute_command(COMMAND.COM_QUERY, "ROLLBACK")
  File "/usr/local/lib/python3.6/site-packages/pymysql/connections.py", line 793, in _execute_command
    raise err.InterfaceError(0, "")
sqlalchemy.exc.InterfaceError: (pymysql.err.InterfaceError) (0, '')
(Background on this error at: http://sqlalche.me/e/13/rvf5)

During handling of the above exception, another exception occurred:

Traceback (most recent call last):
  File "/home/airflow/.local/lib/python3.6/site-packages/airflow/models/taskinstance.py", line 1324, in _run_raw_task
    self._execute_task_with_callbacks(context)
  File "/home/airflow/.local/lib/python3.6/site-packages/airflow/models/taskinstance.py", line 1443, in _execute_task_with_callbacks
    result = self._execute_task(context, self.task)
  File "/home/airflow/.local/lib/python3.6/site-packages/airflow/models/taskinstance.py", line 1494, in _execute_task
    result = execute_callable(context=context)
  File "/home/airflow/.local/lib/python3.6/site-packages/airflow/operators/python.py", line 151, in execute
    return_value = self.execute_callable()
  File "/home/airflow/.local/lib/python3.6/site-packages/airflow/operators/python.py", line 162, in execute_callable
    return self.python_callable(*self.op_args, **self.op_kwargs)
  File "/opt/airflow/dags/ETL/load.py", line 135, in LoadStartSchema
    raise TypeError(e)
TypeError: (pymysql.err.InterfaceError) (0, '')
(Background on this error at: http://sqlalche.me/e/13/rvf5)
[2022-05-15 19:48:00,278] {taskinstance.py:1280} INFO - Marking task as FAILED. dag_id=orchestrator, task_id=load_data, execution_date=20220514T000000, start_date=20220515T194744, end_date=20220515T194800
[2022-05-15 19:48:00,357] {standard_task_runner.py:91} ERROR - Failed to execute job 64 for task load_data
Traceback (most recent call last):
  File "/home/airflow/.local/lib/python3.6/site-packages/pandas/io/sql.py", line 1155, in run_transaction
    yield tx
  File "/home/airflow/.local/lib/python3.6/site-packages/pandas/io/sql.py", line 830, in insert
    exec_insert(conn, keys, chunk_iter)
  File "/home/airflow/.local/lib/python3.6/site-packages/pandas/io/sql.py", line 747, in _execute_insert
    conn.execute(self.table.insert(), data)
  File "/home/airflow/.local/lib/python3.6/site-packages/sqlalchemy/engine/base.py", line 1011, in execute
    return meth(self, multiparams, params)
  File "/home/airflow/.local/lib/python3.6/site-packages/sqlalchemy/sql/elements.py", line 298, in _execute_on_connection
    return connection._execute_clauseelement(self, multiparams, params)
  File "/home/airflow/.local/lib/python3.6/site-packages/sqlalchemy/engine/base.py", line 1130, in _execute_clauseelement
    distilled_params,
  File "/home/airflow/.local/lib/python3.6/site-packages/sqlalchemy/engine/base.py", line 1317, in _execute_context
    e, statement, parameters, cursor, context
  File "/home/airflow/.local/lib/python3.6/site-packages/sqlalchemy/engine/base.py", line 1514, in _handle_dbapi_exception
    util.raise_(exc_info[1], with_traceback=exc_info[2])
  File "/home/airflow/.local/lib/python3.6/site-packages/sqlalchemy/util/compat.py", line 182, in raise_
    raise exception
  File "/home/airflow/.local/lib/python3.6/site-packages/sqlalchemy/engine/base.py", line 1257, in _execute_context
    cursor, statement, parameters, context
  File "/home/airflow/.local/lib/python3.6/site-packages/sqlalchemy/dialects/mysql/mysqldb.py", line 148, in do_executemany
    rowcount = cursor.executemany(statement, parameters)
  File "/usr/local/lib/python3.6/site-packages/pymysql/cursors.py", line 179, in executemany
    self._get_db().encoding,
  File "/usr/local/lib/python3.6/site-packages/pymysql/cursors.py", line 206, in _do_execute_many
    rows += self.execute(sql + postfix)
  File "/usr/local/lib/python3.6/site-packages/pymysql/cursors.py", line 148, in execute
    result = self._query(query)
  File "/usr/local/lib/python3.6/site-packages/pymysql/cursors.py", line 310, in _query
    conn.query(q)
  File "/usr/local/lib/python3.6/site-packages/pymysql/connections.py", line 548, in query
    self._affected_rows = self._read_query_result(unbuffered=unbuffered)
  File "/usr/local/lib/python3.6/site-packages/pymysql/connections.py", line 775, in _read_query_result
    result.read()
  File "/usr/local/lib/python3.6/site-packages/pymysql/connections.py", line 1156, in read
    first_packet = self.connection._read_packet()
  File "/usr/local/lib/python3.6/site-packages/pymysql/connections.py", line 692, in _read_packet
    packet_header = self._read_bytes(4)
  File "/usr/local/lib/python3.6/site-packages/pymysql/connections.py", line 732, in _read_bytes
    data = self._rfile.read(num_bytes)
  File "/usr/local/lib/python3.6/socket.py", line 586, in readinto
    return self._sock.recv_into(b)
  File "/home/airflow/.local/lib/python3.6/site-packages/airflow/models/taskinstance.py", line 1398, in signal_handler
    raise AirflowException("Task received SIGTERM signal")
airflow.exceptions.AirflowException: Task received SIGTERM signal

During handling of the above exception, another exception occurred:

Traceback (most recent call last):
  File "/home/airflow/.local/lib/python3.6/site-packages/sqlalchemy/engine/base.py", line 749, in _rollback_impl
    self.engine.dialect.do_rollback(self.connection)
  File "/home/airflow/.local/lib/python3.6/site-packages/sqlalchemy/dialects/mysql/base.py", line 2513, in do_rollback
    dbapi_connection.rollback()
  File "/usr/local/lib/python3.6/site-packages/pymysql/connections.py", line 479, in rollback
    self._execute_command(COMMAND.COM_QUERY, "ROLLBACK")
  File "/usr/local/lib/python3.6/site-packages/pymysql/connections.py", line 793, in _execute_command
    raise err.InterfaceError(0, "")
pymysql.err.InterfaceError: (0, '')

The above exception was the direct cause of the following exception:

Traceback (most recent call last):
  File "/opt/airflow/dags/ETL/load.py", line 124, in LoadStartSchema
    df_fat.to_sql('FatMovies',dbcon_write,if_exists='replace',index=False)
  File "/home/airflow/.local/lib/python3.6/site-packages/pandas/core/generic.py", line 2615, in to_sql
    method=method,
  File "/home/airflow/.local/lib/python3.6/site-packages/pandas/io/sql.py", line 598, in to_sql
    method=method,
  File "/home/airflow/.local/lib/python3.6/site-packages/pandas/io/sql.py", line 1406, in to_sql
    raise err
  File "/home/airflow/.local/lib/python3.6/site-packages/pandas/io/sql.py", line 1398, in to_sql
    table.insert(chunksize, method=method)
  File "/home/airflow/.local/lib/python3.6/site-packages/pandas/io/sql.py", line 830, in insert
    exec_insert(conn, keys, chunk_iter)
  File "/usr/local/lib/python3.6/contextlib.py", line 99, in __exit__
    self.gen.throw(type, value, traceback)
  File "/home/airflow/.local/lib/python3.6/site-packages/pandas/io/sql.py", line 1157, in run_transaction
    yield self.connectable
  File "/home/airflow/.local/lib/python3.6/site-packages/sqlalchemy/engine/base.py", line 2108, in __exit__
    self.transaction.rollback()
  File "/home/airflow/.local/lib/python3.6/site-packages/sqlalchemy/engine/base.py", line 1751, in rollback
    self._do_rollback()
  File "/home/airflow/.local/lib/python3.6/site-packages/sqlalchemy/engine/base.py", line 1789, in _do_rollback
    self.connection._rollback_impl()
  File "/home/airflow/.local/lib/python3.6/site-packages/sqlalchemy/engine/base.py", line 751, in _rollback_impl
    self._handle_dbapi_exception(e, None, None, None, None)
  File "/home/airflow/.local/lib/python3.6/site-packages/sqlalchemy/engine/base.py", line 1511, in _handle_dbapi_exception
    sqlalchemy_exception, with_traceback=exc_info[2], from_=e
  File "/home/airflow/.local/lib/python3.6/site-packages/sqlalchemy/util/compat.py", line 182, in raise_
    raise exception
  File "/home/airflow/.local/lib/python3.6/site-packages/sqlalchemy/engine/base.py", line 749, in _rollback_impl
    self.engine.dialect.do_rollback(self.connection)
  File "/home/airflow/.local/lib/python3.6/site-packages/sqlalchemy/dialects/mysql/base.py", line 2513, in do_rollback
    dbapi_connection.rollback()
  File "/usr/local/lib/python3.6/site-packages/pymysql/connections.py", line 479, in rollback
    self._execute_command(COMMAND.COM_QUERY, "ROLLBACK")
  File "/usr/local/lib/python3.6/site-packages/pymysql/connections.py", line 793, in _execute_command
    raise err.InterfaceError(0, "")
sqlalchemy.exc.InterfaceError: (pymysql.err.InterfaceError) (0, '')
(Background on this error at: http://sqlalche.me/e/13/rvf5)

During handling of the above exception, another exception occurred:

Traceback (most recent call last):
  File "/home/airflow/.local/lib/python3.6/site-packages/airflow/task/task_runner/standard_task_runner.py", line 85, in _start_by_fork
    args.func(args, dag=self.dag)
  File "/home/airflow/.local/lib/python3.6/site-packages/airflow/cli/cli_parser.py", line 48, in command
    return func(*args, **kwargs)
  File "/home/airflow/.local/lib/python3.6/site-packages/airflow/utils/cli.py", line 92, in wrapper
    return f(*args, **kwargs)
  File "/home/airflow/.local/lib/python3.6/site-packages/airflow/cli/commands/task_command.py", line 292, in task_run
    _run_task_by_selected_method(args, dag, ti)
  File "/home/airflow/.local/lib/python3.6/site-packages/airflow/cli/commands/task_command.py", line 107, in _run_task_by_selected_method
    _run_raw_task(args, ti)
  File "/home/airflow/.local/lib/python3.6/site-packages/airflow/cli/commands/task_command.py", line 184, in _run_raw_task
    error_file=args.error_file,
  File "/home/airflow/.local/lib/python3.6/site-packages/airflow/utils/session.py", line 70, in wrapper
    return func(*args, session=session, **kwargs)
  File "/home/airflow/.local/lib/python3.6/site-packages/airflow/models/taskinstance.py", line 1324, in _run_raw_task
    self._execute_task_with_callbacks(context)
  File "/home/airflow/.local/lib/python3.6/site-packages/airflow/models/taskinstance.py", line 1443, in _execute_task_with_callbacks
    result = self._execute_task(context, self.task)
  File "/home/airflow/.local/lib/python3.6/site-packages/airflow/models/taskinstance.py", line 1494, in _execute_task
    result = execute_callable(context=context)
  File "/home/airflow/.local/lib/python3.6/site-packages/airflow/operators/python.py", line 151, in execute
    return_value = self.execute_callable()
  File "/home/airflow/.local/lib/python3.6/site-packages/airflow/operators/python.py", line 162, in execute_callable
    return self.python_callable(*self.op_args, **self.op_kwargs)
  File "/opt/airflow/dags/ETL/load.py", line 135, in LoadStartSchema
    raise TypeError(e)
TypeError: (pymysql.err.InterfaceError) (0, '')
(Background on this error at: http://sqlalche.me/e/13/rvf5)
[2022-05-15 19:48:00,373] {process_utils.py:66} INFO - Process psutil.Process(pid=1427, status='terminated', exitcode=1, started='19:47:43') (1427) terminated with exit code 1
[2022-05-15 19:49:53,723] {taskinstance.py:1035} INFO - Dependencies all met for <TaskInstance: orchestrator.load_data scheduled__2022-05-14T00:00:00+00:00 [queued]>
[2022-05-15 19:49:53,788] {taskinstance.py:1035} INFO - Dependencies all met for <TaskInstance: orchestrator.load_data scheduled__2022-05-14T00:00:00+00:00 [queued]>
[2022-05-15 19:49:53,788] {taskinstance.py:1241} INFO - 
--------------------------------------------------------------------------------
[2022-05-15 19:49:53,789] {taskinstance.py:1242} INFO - Starting attempt 1 of 2
[2022-05-15 19:49:53,789] {taskinstance.py:1243} INFO - 
--------------------------------------------------------------------------------
[2022-05-15 19:49:53,841] {taskinstance.py:1262} INFO - Executing <Task(PythonOperator): load_data> on 2022-05-14 00:00:00+00:00
[2022-05-15 19:49:53,846] {standard_task_runner.py:52} INFO - Started process 1527 to run task
[2022-05-15 19:49:53,850] {standard_task_runner.py:76} INFO - Running: ['***', 'tasks', 'run', 'orchestrator', 'load_data', 'scheduled__2022-05-14T00:00:00+00:00', '--job-id', '68', '--raw', '--subdir', 'DAGS_FOLDER/pipeline.py', '--cfg-path', '/tmp/tmpqtlyj3ep', '--error-file', '/tmp/tmp707hw862']
[2022-05-15 19:49:53,851] {standard_task_runner.py:77} INFO - Job 68: Subtask load_data
[2022-05-15 19:49:53,920] {logging_mixin.py:109} INFO - Running <TaskInstance: orchestrator.load_data scheduled__2022-05-14T00:00:00+00:00 [running]> on host 87efc59194bd
[2022-05-15 19:49:54,027] {taskinstance.py:1414} INFO - Exporting the following env vars:
AIRFLOW_CTX_DAG_EMAIL=***@example.com
AIRFLOW_CTX_DAG_OWNER=***
AIRFLOW_CTX_DAG_ID=orchestrator
AIRFLOW_CTX_TASK_ID=load_data
AIRFLOW_CTX_EXECUTION_DATE=2022-05-14T00:00:00+00:00
AIRFLOW_CTX_DAG_RUN_ID=scheduled__2022-05-14T00:00:00+00:00
[2022-05-15 19:49:54,028] {load.py:17} INFO - Starting process load star schema
[2022-05-15 19:49:54,045] {base.py:79} INFO - Using connection to: id: MySql Localhost. Host: 192.168.15.14, Port: 3306, Schema: , Login: db_user, Password: ***, extra: {}
[2022-05-15 19:49:54,527] {load.py:39} INFO - Creating Dim Torrent
[2022-05-15 19:49:54,542] {base.py:79} INFO - Using connection to: id: MySql Localhost. Host: 192.168.15.14, Port: 3306, Schema: , Login: db_user, Password: ***, extra: {}
[2022-05-15 19:50:00,846] {base.py:79} INFO - Using connection to: id: MySql Localhost. Host: 192.168.15.14, Port: 3306, Schema: , Login: db_user, Password: ***, extra: {}
[2022-05-15 19:50:00,984] {load.py:62} INFO - Insert lines in Dim Torrent 2025
[2022-05-15 19:50:00,984] {load.py:63} INFO - Completed creation Dim Torrent
[2022-05-15 19:50:00,984] {load.py:74} INFO - Creating Dim Genres
[2022-05-15 19:50:01,013] {base.py:79} INFO - Using connection to: id: MySql Localhost. Host: 192.168.15.14, Port: 3306, Schema: , Login: db_user, Password: ***, extra: {}
[2022-05-15 19:50:03,238] {base.py:79} INFO - Using connection to: id: MySql Localhost. Host: 192.168.15.14, Port: 3306, Schema: , Login: db_user, Password: ***, extra: {}
[2022-05-15 19:50:03,404] {load.py:95} INFO - Insert lines in Dim Genres 223
[2022-05-15 19:50:03,404] {load.py:96} INFO - Completed creation Dim Genres
[2022-05-15 19:50:03,405] {load.py:107} INFO - Creating Fat Movies
[2022-05-15 19:50:03,436] {base.py:79} INFO - Using connection to: id: MySql Localhost. Host: 192.168.15.14, Port: 3306, Schema: , Login: db_user, Password: ***, extra: {}
[2022-05-15 19:50:10,053] {base.py:79} INFO - Using connection to: id: MySql Localhost. Host: 192.168.15.14, Port: 3306, Schema: , Login: db_user, Password: ***, extra: {}
[2022-05-15 19:50:10,222] {load.py:129} INFO - Insert lines in Fat Movies 2025
[2022-05-15 19:50:10,222] {load.py:130} INFO - Completed creation Fat Movies
[2022-05-15 19:50:10,223] {load.py:138} INFO - Completed process load start schema
[2022-05-15 19:50:10,226] {python.py:152} INFO - Done. Returned value was: None
[2022-05-15 19:50:10,271] {taskinstance.py:1280} INFO - Marking task as SUCCESS. dag_id=orchestrator, task_id=load_data, execution_date=20220514T000000, start_date=20220515T194953, end_date=20220515T195010
[2022-05-15 19:50:10,328] {local_task_job.py:154} INFO - Task exited with return code 0
[2022-05-15 19:50:10,408] {local_task_job.py:264} INFO - 0 downstream tasks scheduled from follow-on schedule check
